Workbook

Sheet Deal Overview
B2: Project Solomeo
B3: Kering S.A. — Acquisition of Brunello Cucinelli S.p.A.
B4: Confidential Discussion Materials | June 2026
B6: Transaction Summary
B7: Acquirer | C7: Kering S.A.
B8: Target | C8: Brunello Cucinelli S.p.A.
B9: Transaction Type | C9: Acquisition (Cash&Stock)
B10: Offer Price per Share | C10: 125 | D10: Source: Assumption
B11: Unaffected Share Price | C11: 98 | D11: Source: Bloomberg, Jun 2026 (30-day VWAP)
B12: Premium to Unaffected | C12: =(C10-C11)/C11 -> 0.2755102
B13: Shares Outstanding (M) | C13: 68 | D13: Source: Cucinelli FY2025 Annual Report, p.112
B14: Equity Value (€M) | C14: =C10*C13 -> 8500
B15: Plus: Net Debt (€M) | C15: ='Cucinelli Financials'!H42 -> 45 | D15: Source: Cucinelli FY2025 Annual Report, p.89
B16: Enterprise Value (€M) | C16: =C14+C15 -> 8545
B17: Implied EV / LTM EBITDA | C17: =C16/'Cucinelli Financials'!H12 -> 24.696532
B18: Implied EV / LTM Revenue | C18: =C16/'Cucinelli Financials'!H6 -> 6.6757812
B20: Strategic Rationale
B21: 1. Kering’s overexposure to Gucci (~50% of group revenue) creates concentration risk amid brand fatigue
B22: 2. Cucinelli is the undisputed leader in quiet luxury, the fastest-growing luxury subsegment
B23: 3. Cucinelli’s DTC mix shift (50/50 → 33/67 wholesale-to-retail) aligns with Kering’s direct-to-consumer strategy
B24: 4. Run-rate cost synergies of €80–120M achievable via supply chain consolidation and shared distribution
B25: 5. Defensive rationale: prevents LVMH or Richemont from acquiring a key competitor in Italian luxury
B27: Consideration Mix
B28: Component | C28: Amount (€M) | D28: % of Total
B29: Cash | C29: 5100 | D29: =C29/$C$31 -> 0.6
B30: Stock (New Kering Shares) | C30: 3400 | D30: =C30/$C$31 -> 0.4
B31: Total Consideration | C31: =C29+C30 -> 8500 | D31: =D29+D30 -> 1
A34: Strictly Private & Confidential — For Discussion Purposes Only

Sheet Cucinelli Financials
B2: Brunello Cucinelli S.p.A. — Historical Financials
B4: Income Statement (€M)
C5: FY2020 | D5: FY2021 | E5: FY2022 | F5: FY2023 | G5: FY2024 | H5: FY2025 | I5: Source
B6: Revenue | C6: 544 | D6: 712 | E6: 906 | F6: 1100 | G6: 1142 | H6: 1280 | I6: Annual Report, Consolidated P&L
B7: YoY Growth % | D7: 0.309 | E7: 0.272 | F7: 0.214 | G7: 0.038 | H7: 0.121
B8: COGS | C8: 163 | D8: 207 | E8: 263 | F8: 308 | G8: 314 | H8: 320 | I8: Annual Report, Consolidated P&L
B9: Gross Profit | C9: =C6-C8 -> 381 | D9: =D6-D8 -> 505 | E9: =E6-E8 -> 643 | F9: =F6-F8 -> 792 | G9: =G6-G8 -> 828 | H9: =H6-H8 -> 960 | I9: Calculated: Revenue − COGS
B10: Gross Margin % | C10: =C9/C6 -> 0.70036765 | D10: =D9/D6 -> 0.70926966 | E10: =E9/E6 -> 0.70971302 | F10: =F9/F6 -> 0.72 | G10: =G9/G6 -> 0.72504378 | H10: =H9/H6 -> 0.75
B11: SG&A | C11: 250 | D11: 312 | E11: 389 | F11: 466 | G11: 476 | H11: 614 | I11: FY2025 SG&A +29% YoY reflects: (1) 8 new flagship openings incl. NY Madison Ave & Tokyo Ginza; (2) €40M one-time store renovation programme; (3) elevated digital marketing for DTC push. Recurring SG&A growth ~12%, in line with revenue. Source: FY2025 Annual Report, MD&A p.34
B12: EBITDA | C12: =C9-C11 -> 131 | D12: =D9-D11 -> 193 | E12: =E9-E11 -> 254 | F12: =F9-F11 -> 326 | G12: =G9-G11 -> 352 | H12: =H9-H11 -> 346 | I12: Calculated: Gross Profit − SG&A
B13: EBITDA Margin % | C13: =C12/C6 -> 0.24080882 | D13: =D12/D6 -> 0.27106742 | E13: =E12/E6 -> 0.2803532 | F13: =F12/F6 -> 0.29636364 | G13: =G12/G6 -> 0.30823117 | H13: =H12/H6 -> 0.2703125
B14: D&A | C14: 48 | D14: 55 | E14: 65 | F14: 74 | G14: 78 | H14: 82 | I14: Annual Report, Note 8
B15: EBIT | C15: =C12-C14 -> 83 | D15: =D12-D14 -> 138 | E15: =E12-E14 -> 189 | F15: =F12-F14 -> 252 | G15: =G12-G14 -> 274 | H15: =H12-H14 -> 264 | I15: Calculated: EBITDA − D&A
B16: EBIT Margin % | C16: =C15/C6 -> 0.15257353 | D16: =D15/D6 -> 0.19382022 | E16: =E15/E6 -> 0.20860927 | F16: =F15/F6 -> 0.22909091 | G16: =G15/G6 -> 0.23992995 | H16: =H15/H6 -> 0.20625
B17: Interest Expense | C17: 8 | D17: 7 | E17: 9 | F17: 12 | G17: 11 | H17: 10 | I17: Annual Report, Note 12
B18: EBT | C18: =C15-C17 -> 75 | D18: =D15-D17 -> 131 | E18: =E15-E17 -> 180 | F18: =F15-F17 -> 240 | G18: =G15-G17 -> 263 | H18: =H15-H17 -> 254 | I18: Calculated: EBIT − Interest
B19: Taxes (26%) | C19: =C18*$C$50 -> 19.5 | D19: =D18*$C$50 -> 34.06 | E19: =E18*$C$50 -> 46.8 | F19: =F18*$C$50 -> 62.4 | G19: =G18*$C$50 -> 68.38 | H19: =H18*$C$50 -> 66.04 | I19: Italian corporate rate (IRES + IRAP)
B20: Net Income | C20: =C18-C19 -> 55.5 | D20: =D18-D19 -> 96.94 | E20: =E18-E19 -> 133.2 | F20: =F18-F19 -> 177.6 | G20: =G18-G19 -> 194.62 | H20: =H18-H19 -> 187.96
B21: Net Margin % | C21: =C20/C6 -> 0.10202206 | D21: =D20/D6 -> 0.13615169 | E21: =E20/E6 -> 0.14701987 | F21: =F20/F6 -> 0.16145455 | G21: =G20/G6 -> 0.17042032 | H21: =H20/H6 -> 0.14684375
B23: Revenue by Channel (€M)
C24: FY2020 | D24: FY2021 | E24: FY2022 | F24: FY2023 | G24: FY2024 | H24: FY2025 | I24: Source
B25: Retail (DTC) | C25: 272 | D25: 385 | E25: 535 | F25: 726 | G25: 777 | H25: 858 | I25: Annual Report, Note 5
B26: % of Revenue | C26: =C25/C6 -> 0.5 | D26: =D25/D6 -> 0.54073034 | E26: =E25/E6 -> 0.59050773 | F26: =F25/F6 -> 0.66 | G26: =G25/G6 -> 0.68038529 | H26: =H25/H6 -> 0.6703125
B27: Wholesale | C27: 272 | D27: 327 | E27: 371 | F27: 374 | G27: 365 | H27: 422 | I27: Annual Report, Note 5
B28: % of Revenue | C28: =C27/C6 -> 0.5 | D28: =D27/D6 -> 0.45926966 | E28: =E27/E6 -> 0.40949227 | F28: =F27/F6 -> 0.34 | G28: =G27/G6 -> 0.31961471 | H28: =H27/H6 -> 0.3296875
B30: Revenue by Geography (€M)
C31: FY2020 | D31: FY2021 | E31: FY2022 | F31: FY2023 | G31: FY2024 | H31: FY2025 | I31: Source
B32: Europe | C32: 207 | D32: 271 | E32: 344 | F32: 396 | G32: 400 | H32: 448 | I32: Annual Report, Note 5
B33: Americas | C33: 141 | D33: 192 | E33: 254 | F33: 308 | G33: 297 | H33: 333 | I33: Annual Report, Note 5
B34: Asia & RoW | C34: 196 | D34: 249 | E34: 308 | F34: 396 | G34: 445 | H34: 499 | I34: Annual Report, Note 5
B35: Total Revenue (check) | C35: =C32+C33+C34 -> 544 | D35: =D32+D33+D34 -> 712 | E35: =E32+E33+E34 -> 906 | F35: =F32+F33+F34 -> 1100 | G35: =G32+G33+G34 -> 1142 | H35: =H32+H33+H34 -> 1280
B37: Key Balance Sheet Items (€M)
C38: FY2020 | D38: FY2021 | E38: FY2022 | F38: FY2023 | G38: FY2024 | H38: FY2025
B39: Total Assets | C39: 1200 | D39: 1380 | E39: 1600 | F39: 1850 | G39: 1920 | H39: 2050
B40: Total Debt | C40: 180 | D40: 160 | E40: 140 | F40: 120 | G40: 100 | H40: 95
B41: Cash & Equivalents | C41: 85 | D41: 70 | E41: 60 | F41: 55 | G41: 50 | H41: 50
B42: Net Debt | C42: =C40-C41 -> 95 | D42: =D40-D41 -> 90 | E42: =E40-E41 -> 80 | F42: =F40-F41 -> 65 | G42: =G40-G41 -> 50 | H42: =H40-H41 -> 45
B43: Shareholders' Equity | C43: 680 | D43: 760 | E43: 870 | F43: 1020 | G43: 1180 | H43: 1340
B45: Key Ratios
C46: FY2020 | D46: FY2021 | E46: FY2022 | F46: FY2023 | G46: FY2024 | H46: FY2025
...

Sheet Projections
B2: Brunello Cucinelli S.p.A. — Projections
B4: Key Assumptions
B5: Assumption | C5: FY2026E | D5: FY2027E | E5: FY2028E | F5: FY2029E | G5: FY2030E | H5: Rationale
B6: Revenue Growth | C6: 0.1 | D6: 0.09 | E6: 0.08 | F6: 0.07 | G6: 0.06 | H6: Gradual deceleration from luxury normalisation
B7: Gross Margin | C7: 0.755 | D7: 0.76 | E7: 0.765 | F7: 0.77 | G7: 0.77 | H7: DTC mix shift drives margin expansion
B8: EBITDA Margin | C8: 0.28 | D8: 0.285 | E8: 0.29 | F8: 0.295 | G8: 0.3 | H8: Operating leverage on fixed SG&A base
B9: D&A % of Revenue | C9: 0.063 | D9: 0.062 | E9: 0.061 | F9: 0.06 | G9: 0.06 | H9: Stable asset base, declining as % of revenue
B10: CapEx % of Revenue | C10: 0.07 | D10: 0.07 | E10: 0.065 | F10: 0.065 | G10: 0.06 | H10: Retail expansion tapering off post-2028
B11: Change in NWC % of ΔRev | C11: 0.05 | D11: 0.05 | E11: 0.05 | F11: 0.05 | G11: 0.05 | H11: In line with historical avg (4.5–5.5%)
B12: Tax Rate | C12: 0.26 | D12: 0.26 | E12: 0.26 | F12: 0.26 | G12: 0.26 | H12: Italian statutory rate (IRES 24% + IRAP 3.9%)
B13: Interest Expense Assumption (€M) | C13: 10.5 | D13: 11 | E13: 11.5 | F13: 12 | G13: 12.5 | H13: Estimated standalone interest on €45M net debt; grows with minor refinancing
B15: Projected Income Statement (€M)
C16: FY2026E | D16: FY2027E | E16: FY2028E | F16: FY2029E | G16: FY2030E
B17: Revenue | C17: ='Cucinelli Financials'!H6*(1+C6) -> 1408 | D17: =C17*(1+D6) -> 1534.72 | E17: =D17*(1+E6) -> 1657.4976 | F17: =E17*(1+F6) -> 1773.5224 | G17: =F17*(1+G6) -> 1879.9338
B18: YoY Growth % | C18: =C6 -> 0.1 | D18: =D6 -> 0.09 | E18: =E6 -> 0.08 | F18: =F6 -> 0.07 | G18: =G6 -> 0.06
B19: Gross Profit | C19: =C17*C7 -> 1063.04 | D19: =D17*D7 -> 1166.3872 | E19: =E17*E7 -> 1267.9857 | F19: =F17*F7 -> 1365.6123 | G19: =G17*G7 -> 1447.549
B20: Gross Margin % | C20: =C7 -> 0.755 | D20: =D7 -> 0.76 | E20: =E7 -> 0.765 | F20: =F7 -> 0.77 | G20: =G7 -> 0.77
B21: EBITDA | C21: =C17*C8 -> 394.24 | D21: =D17*D8 -> 437.3952 | E21: =E17*E8 -> 480.6743 | F21: =F17*F8 -> 523.18912 | G21: =G17*G8 -> 563.98013
B22: EBITDA Margin % | C22: =C8 -> 0.28 | D22: =D8 -> 0.285 | E22: =E8 -> 0.29 | F22: =F8 -> 0.295 | G22: =G8 -> 0.3
B23: D&A | C23: =C17*C9 -> 88.704 | D23: =D17*D9 -> 95.15264 | E23: =E17*E9 -> 101.10735 | F23: =F17*F9 -> 106.41135 | G23: =G17*G9 -> 112.79603
B24: EBIT | C24: =C21-C23 -> 305.536 | D24: =D21-D23 -> 342.24256 | E24: =E21-E23 -> 379.56695 | F24: =F21-F23 -> 416.77777 | G24: =G21-G23 -> 451.18411
B25: EBIT Margin % | C25: =C24/C17 -> 0.217 | D25: =D24/D17 -> 0.223 | E25: =E24/E17 -> 0.229 | F25: =F24/F17 -> 0.235 | G25: =G24/G17 -> 0.24
B26: Interest Expense | C26: =C13 -> 10.5 | D26: =D13 -> 11 | E26: =E13 -> 11.5 | F26: =F13 -> 12 | G26: =G13 -> 12.5
B27: EBT | C27: =C24-C26 -> 295.036 | D27: =D24-D26 -> 331.24256 | E27: =E24-E26 -> 368.06695 | F27: =F24-F26 -> 404.77777 | G27: =G24-G26 -> 438.68411
B28: Taxes on EBT (26%) | C28: =C27*$C$12 -> 76.70936 | D28: =D27*$C$12 -> 86.123066 | E28: =E27*$C$12 -> 95.697407 | F28: =F27*$C$12 -> 105.24222 | G28: =G27*$C$12 -> 114.05787
B29: Net Income | C29: =C27-C28 -> 218.32664 | D29: =D27-D28 -> 245.11949 | E29: =E27-E28 -> 272.36954 | F29: =F27-F28 -> 299.53555 | G29: =G27-G28 -> 324.62624
B31: Unlevered Free Cash Flow Build (€M)
C32: FY2026E | D32: FY2027E | E32: FY2028E | F32: FY2029E | G32: FY2030E
B33: EBIT | C33: =C24 -> 305.536 | D33: =D24 -> 342.24256 | E33: =E24 -> 379.56695 | F33: =F24 -> 416.77777 | G33: =G24 -> 451.18411
B34: Less: Taxes on EBIT (26%) | C34: =C33*$C$12 -> 79.43936 | D34: =D33*$C$12 -> 88.983066 | E34: =E33*$C$12 -> 98.687407 | F34: =F33*$C$12 -> 108.36222 | G34: =G33*$C$12 -> 117.30787
B35: NOPAT | C35: =C33-C34 -> 226.09664 | D35: =D33-D34 -> 253.25949 | E35: =E33-E34 -> 280.87954 | F35: =F33-F34 -> 308.41555 | G35: =G33-G34 -> 333.87624
B36: Plus: D&A | C36: =C23 -> 88.704 | D36: =D23 -> 95.15264 | E36: =E23 -> 101.10735 | F36: =F23 -> 106.41135 | G36: =G23 -> 112.79603
B37: Less: CapEx | C37: =C17*C10 -> 98.56 | D37: =D17*D10 -> 107.4304 | E37: =E17*E10 -> 107.73734 | F37: =F17*F10 -> 115.27896 | G37: =G17*G10 -> 112.79603
B38: Less: Change in NWC | C38: =(C17-'Cucinelli Financials'!H6)*$C$11 -> 6.4 | D38: =(D17-C17)*$D$11 -> 6.336 | E38: =(E17-D17)*$E$11 -> 6.13888 | F38: =(F17-E17)*$F$11 -> 5.8012416 | G38: =(G17-F17)*$G$11 -> 5.3205673
B39: Unlevered Free Cash Flow | C39: =C35+C36-C37-C38 -> 209.84064 | D39: =D35+D36-D37-D38 -> 234.64573 | E39: =E35+E36-E37-E38 -> 268.11067 | F39: =F35+F36-F37-F38 -> 293.7467 | G39: =G35+G36-G37-G38 -> 328.55567
A42: Strictly Private & Confidential — For Discussion Purposes Only

Sheet DCF Valuation
B2: Discounted Cash Flow Valuation
B4: WACC Calculation
B5: Risk-Free Rate (EUR 10Y Bund) | C5: 0.035 | D5: Source: ECB, Jun 2026
B6: Equity Risk Premium | C6: 0.055 | D6: Source: Damodaran, Jan 2026
B7: Levered Beta | C7: 0.95 | D7: Source: Bloomberg, 2Y weekly vs. STOXX 600
B8: Cost of Equity (Ke) | C8: =C5+C7*C6 -> 0.08725 | D8: CAPM: Rf + β × ERP
B9: Pre-Tax Cost of Debt (Kd) | C9: 0.045 | D9: Source: Cucinelli bond yield, Jun 2026
B10: Tax Rate | C10: 0.26 | D10: Italian statutory (IRES 24% + IRAP ~2%)
B11: After-Tax Cost of Debt | C11: =C9*(1-C10) -> 0.0333
B12: Debt / Total Capital | C12: 0.034 | D12: Source: Cucinelli FY2025 B/S | E12: Note: Model uses book-value D/Capital = 3.4%. Market-value weights: D/(D+MktEq) = €95M/(€95M+€8,500M) = 1.1%. Delta to WACC = ~3bps (immaterial). Recommend updating to market weights for defensibility in technical screen.
B13: Equity / Total Capital | C13: =1-C12 -> 0.966
B14: WACC | C14: =C8*C13+C11*C12 -> 0.0854157
B16: DCF Valuation (€M)
C17: FY2026E | D17: FY2027E | E17: FY2028E | F17: FY2029E | G17: FY2030E
B18: Unlevered FCF | C18: =Projections!C39 -> 209.84064 | D18: =Projections!D39 -> 234.64573 | E18: =Projections!E39 -> 268.11067 | F18: =Projections!F39 -> 293.7467 | G18: =Projections!G39 -> 328.55567
B19: Discount Factor | C19: =1/(1+$C$14)^0.5 -> 0.95984686 | D19: =1/(1+$C$14)^1.5 -> 0.88431268 | E19: =1/(1+$C$14)^2.5 -> 0.81472258 | F19: =1/(1+$C$14)^3.5 -> 0.7506088 | G19: =1/(1+$C$14)^4.5 -> 0.6915404 | H19: Mid-year convention (MS standard): cash flows assumed at mid-year; TV at end of Year 5
B20: PV of FCF | C20: =C18*C19 -> 201.41488 | D20: =D18*D19 -> 207.5002 | E20: =E18*E19 -> 218.43582 | F20: =F18*F19 -> 220.48886 | G20: =G18*G19 -> 227.20952
B21: Sum of PV of FCFs | C21: =SUM(C20:G20) -> 1075.0493
B23: Terminal Value
B24: Terminal Growth Rate (g) | C24: 0.025 | D24: Eurozone long-run nominal GDP growth
B25: Exit EV/EBITDA Multiple | C25: 18 | D25: In line with luxury sector 5Y avg
B27: Method 1: Perpetuity Growth
B28: TV = FCF₀ × (1+g) / (WACC – g) | C28: =Projections!G39*(1+C24)/(C14-C24) -> 5574.2061
B29: PV of Terminal Value | C29: =C28/(1+$C$14)^5 -> 3700.0068
B30: TV as % of Total EV | C30: =C29/(C21+C29) -> 0.77486144
B32: Method 2: Exit Multiple
B33: TV = EBITDA₀ × Multiple | C33: =Projections!G21*C25 -> 10151.642
B34: PV of Terminal Value | C34: =C33/(1+$C$14)^5 -> 6738.3849
B35: TV as % of Total EV | C35: =C34/(C21+C34) -> 0.86241015
B37: Enterprise Value Bridge to Equity Value
C38: Perpetuity Growth | D38: Exit Multiple
B39: PV of FCFs (FY2026–2030) | C39: =C21 -> 1075.0493 | D39: =C21 -> 1075.0493
B40: PV of Terminal Value | C40: =C29 -> 3700.0068 | D40: =C34 -> 6738.3849
B41: Enterprise Value | C41: =C39+C40 -> 4775.0561 | D41: =D39+D40 -> 7813.4342
B42: Less: Net Debt | C42: =-'Deal Overview'!$C$15 -> -45 | D42: =-'Deal Overview'!$C$15 -> -45
B43: Equity Value | C43: =C41+C42 -> 4730.0561 | D43: =D41+D42 -> 7768.4342
B44: Shares Outstanding (M) | C44: ='Deal Overview'!$C$13 -> 68 | D44: ='Deal Overview'!$C$13 -> 68
B45: Implied Share Price | C45: =C43/C44 -> 69.559649 | D45: =D43/D44 -> 114.24168
B47: Midpoint Implied Share Price | C47: =(C45+D45)/2 -> 91.900664
B49: Sensitivity Analysis: Implied Share Price (€)
...

Sheet Trading Comps
B2: Comparable Company Analysis — FY2025
B3: All market data as of June 2026. Financials from latest annual filings.
B5: Company | C5: Mkt Cap (€B) | D5: EV (€B) | E5: Rev (€B) | F5: EBITDA (€B) | G5: Net Inc (€B) | H5: EV/Rev | I5: EV/EBITDA | J5: P/E | K5: EBITDA Margin
B6: Hermès | C6: 220 | D6: 218 | E6: 14.5 | F6: 7.8 | G6: 4.5 | H6: =D6/E6 -> 15.034483 | I6: =D6/F6 -> 27.948718 | J6: =C6/G6 -> 48.888889 | K6: 0.538
B7: LVMH | C7: 310 | D7: 340 | E7: 85 | F7: 24.3 | G7: 14.1 | H7: =D7/E7 -> 4 | I7: =D7/F7 -> 13.99177 | J7: =C7/G7 -> 21.985816 | K7: 0.286
B8: Moncler | C8: 16 | D8: 17.5 | E8: 3.2 | F8: 1 | G8: 0.6 | H8: =D8/E8 -> 5.46875 | I8: =D8/F8 -> 17.5 | J8: =C8/G8 -> 26.666667 | K8: 0.313
B9: Prada | C9: 22 | D9: 23.5 | E9: 5.4 | F9: 1.6 | G9: 1 | H9: =D9/E9 -> 4.3518519 | I9: =D9/F9 -> 14.6875 | J9: =C9/G9 -> 22 | K9: 0.296
B10: Kering (Acquirer) | C10: 26 | D10: 35 | E10: 17.5 | F10: 4.5 | G10: 2.1 | H10: =D10/E10 -> 2 | I10: =D10/F10 -> 7.7777778 | J10: =C10/G10 -> 12.380952 | K10: 0.257
B11: Zegna | C11: 3.5 | D11: 5 | E11: 2.1 | F11: 0.5 | G11: 0.2 | H11: =D11/E11 -> 2.3809524 | I11: =D11/F11 -> 10 | J11: =C11/G11 -> 17.5 | K11: 0.238
B12: Ferragamo | C12: 2.8 | D12: 3.3 | E12: 1.3 | F12: 0.2 | G12: 0.1 | H12: =D12/E12 -> 2.5384615 | I12: =D12/F12 -> 16.5 | J12: =C12/G12 -> 28 | K12: 0.154
B13: Mean (ex-Kering) | H13: =AVERAGE(H6,H7,H8,H9,H11,H12) -> 5.6290831 | I13: =AVERAGE(I6,I7,I8,I9,I11,I12) -> 16.771331 | J13: =AVERAGE(J6,J7,J8,J9,J11,J12) -> 27.506895
B14: Median (ex-Kering) | H14: =MEDIAN(H6,H7,H8,H9,H11,H12) -> 4.1759259 | I14: =MEDIAN(I6,I7,I8,I9,I11,I12) -> 15.59375 | J14: =MEDIAN(J6,J7,J8,J9,J11,J12) -> 24.333333
B16: Implied Cucinelli Valuation (€M)
C17: EV/Revenue | D17: EV/EBITDA | E17: P/E (Equity Value)
B18: Cucinelli LTM Metric | C18: ='Cucinelli Financials'!H6 -> 1280 | D18: ='Cucinelli Financials'!H12 -> 346 | E18: ='Cucinelli Financials'!H20 -> 187.96
B19: At Median Multiple → EV | C19: =H14*C18 -> 5345.1852 | D19: =I14*D18 -> 5395.4375 | E19: =J14*E18 -> 4573.6933 | F19: Note: EV/Revenue and EV/EBITDA give Enterprise Value; P/E column gives Equity Value (market cap) directly — no net debt adjustment needed
B20: At Mean Multiple → EV | C20: =H13*C18 -> 7205.2264 | D20: =I13*D18 -> 5802.8806 | E20: =J13*E18 -> 5170.196
B22: Implied Price/Share (Median) | C22: =(C19-'Deal Overview'!$C$15)/'Deal Overview'!$C$13 -> 77.9439 | D22: =(D19-'Deal Overview'!$C$15)/'Deal Overview'!$C$13 -> 78.682904 | E22: =E19/'Deal Overview'!$C$13 -> 67.260196 | F22: P/E → Equity Value per share (no net debt adj)
B23: Implied Price/Share (Mean) | C23: =(C20-'Deal Overview'!$C$15)/'Deal Overview'!$C$13 -> 105.29745 | D23: =(D20-'Deal Overview'!$C$15)/'Deal Overview'!$C$13 -> 84.674715 | E23: =E20/'Deal Overview'!$C$13 -> 76.032294
A26: Strictly Private & Confidential — For Discussion Purposes Only

Sheet Precedent Transactions
B2: Precedent Transaction Analysis — Luxury / Premium Consumer
B4: Acquirer | C4: Target | D4: Year | E4: EV (€B) | F4: EV/Rev | G4: EV/EBITDA | H4: Premium | I4: Source
B5: LVMH | C5: Tiffany & Co. | D5: 2021 | E5: 14.7 | F5: 5.6 | G5: 16.5 | H5: 0.37 | I5: LVMH press release, Jan 2021
B6: Capri Holdings | C6: Versace | D6: 2018 | E6: 1.8 | F6: 2.3 | G6: 14 | H6: n/a | I6: Capri Holdings 8-K, Sep 2018
B7: Tapestry | C7: Capri Holdings | D7: 2023 | E7: 8 | F7: 1.5 | G7: 9.2 | H7: 0.28 | I7: Tapestry press release, Aug 2023
B8: Coach | C8: Kate Spade | D8: 2017 | E8: 2.2 | F8: 1.7 | G8: 16 | H8: 0.27 | I8: Tapestry 8-K, May 2017
B9: Michael Kors | C9: Jimmy Choo | D9: 2017 | E9: 1.1 | F9: 2.2 | G9: 13 | H9: 0.36 | I9: Capri Holdings 8-K, Jul 2017
B10: Richemont | C10: Watchfinder | D10: 2018 | E10: 0.2 | F10: n/a | G10: n/a | H10: n/a | I10: Richemont press release, Jun 2018
B11: Mean | F11: =AVERAGE(F5,F6,F7,F8,F9) -> 2.66 | G11: =AVERAGE(G5,G6,G7,G8,G9) -> 13.74 | H11: =AVERAGE(H5,H7,H8,H9) -> 0.32
B12: Median | F12: =MEDIAN(F5,F6,F7,F8,F9) -> 2.2 | G12: =MEDIAN(G5,G6,G7,G8,G9) -> 14 | H12: =MEDIAN(H5,H7,H8,H9) -> 0.32
B14: Implied Cucinelli Valuation at Precedent Medians (€M)
B15: EV/Revenue (Median) × Revenue | E15: =F12*'Cucinelli Financials'!H6 -> 2816
B16: EV/EBITDA (Median) × EBITDA | E16: =G12*'Cucinelli Financials'!H12 -> 4844
B18: Implied Price/Share (EV/Revenue) | E18: =(E15-'Deal Overview'!$C$15)/'Deal Overview'!$C$13 -> 40.75
B19: Implied Price/Share (EV/EBITDA) | E19: =(E16-'Deal Overview'!$C$15)/'Deal Overview'!$C$13 -> 70.573529
B21: Note: Precedent multiples are lower than trading comps — most targets (Versace, Capri, Kate Spade) were mid-tier or distressed brands. Cucinelli’s premium positioning justifies multiples well above the precedent median.
A24: Strictly Private & Confidential — For Discussion Purposes Only

Sheet Sources & Uses
B2: Sources & Uses of Funds (€M)
B4: Sources | C4: Amount (€M) | D4: % of Total | F4: Uses | G4: Amount (€M) | H4: % of Total
B5: Revolving Credit Facility Draw | C5: 500 | D5: =C5/C10 -> 0.058823529 | F5: Equity Purchase Price | G5: 8500 | H5: =G5/G10 -> 1
B6: New Term Loan A (5Y) | C6: 1500 | D6: =C6/C10 -> 0.17647059 | F6: Repay Existing Cucinelli Debt | G6: ='Cucinelli Financials'!H40 -> 95 | H6: =G6/G10 -> 0.011176471
B7: New Term Loan B (7Y) | C7: 1600 | D7: =C7/C10 -> 0.18823529 | F7: Transaction Fees (est. 1.5%) | G7: =G5*$C$22 -> 127.5 | H7: =G7/G10 -> 0.015
B8: Cash on Balance Sheet | C8: 1500 | D8: =C8/C10 -> 0.17647059 | F8: Financing Fees (est. 2.0% of debt) | G8: =(C5+C6+C7)*$C$23 -> 72 | H8: =G8/G10 -> 0.0084705882
B9: New Kering Equity Issued | C9: 3400 | D9: =C9/C10 -> 0.4 | F9: Balancing Item — Net Cash Draw from Kering Reserves | G9: =C10-G5-G6-G7-G8 -> -294.5 | H9: =G9/G10 -> -0.034647059
B10: Total Sources | C10: =SUM(C5:C9) -> 8500 | D10: 1 | F10: Total Uses | G10: =SUM(G5:G9) -> 8500 | H10: 1
B12: Sources - Uses (must be zero) | C12: =C10-G10 -> 0 | F12: Note: The negative balancing item (€(294.5)M) reflects that total acquisition costs slightly exceed the sum of new financing raised + Cucinelli equity price. This represents additional cash drawn from Kering existing reserves. All items net to zero; Sources = Uses = €8,500M.
B14: Debt Summary Post-Transaction
B15: Instrument | C15: Amount (€M) | D15: Rate | E15: Maturity
B16: Revolving Credit Facility | C16: 500 | D16: 0.04 | E16: 2031
B17: Term Loan A | C17: 1500 | D17: 0.045 | E17: 2031
B18: Term Loan B | C18: 1600 | D18: 0.055 | E18: 2033
B19: Existing Kering Debt | C19: 9000 | D19: 0.035 | E19: Various
B20: Total Pro Forma Debt | C20: =SUM(C16:C19) -> 12600
B21: Pro Forma Net Debt / EBITDA | C21: =C20/('Trading Comps'!F10*1000+'Cucinelli Financials'!H12) -> 2.6000825 | E21: Combined Kering + Cucinelli EBITDA
B22: Transaction Fee % (of equity purchase) | C22: 0.015
B23: Financing Fee % (of new debt) | C23: 0.02
A24: Strictly Private & Confidential — For Discussion Purposes Only

Sheet Synergy Analysis
B2: Synergy Analysis — Cost & Revenue Synergies
B4: Cost Synergies Breakdown (€M, Run-Rate)
B5: Category | C5: Run-Rate (€M) | D5: Rationale
B6: Procurement & Raw Materials | C6: 35 | D6: Consolidated leather/cashmere sourcing across Kering brands
B7: SG&A & Headcount | C7: 25 | D7: Elimination of duplicate corporate functions (finance, legal, HR, IT)
B8: Distribution & Logistics | C8: 20 | D8: Shared European warehouse network and last-mile logistics
B9: Marketing & Digital | C9: 10 | D9: Consolidated digital platform and shared media buying scale
B10: IT & Systems Integration | C10: 10 | D10: Single ERP and CRM platform migration
B11: Total Cost Synergies (Run-Rate) | C11: =SUM(C6:C10) -> 100
B13: Revenue Synergies (€M, Run-Rate)
B14: Category | C14: Run-Rate (€M) | D14: Rationale
B15: Cross-selling via Kering DTC | C15: 15 | D15: Cucinelli products in Kering e-commerce ecosystem
B16: Asia-Pacific Distribution | C16: 10 | D16: Leverage Kering's established Asia retail footprint
B17: Pricing Power (Brand Halo) | C17: 5 | D17: Modest price increases from association with Kering luxury portfolio
B18: Total Revenue Synergies (Run-Rate) | C18: =SUM(C15:C17) -> 30
B20: Total Combined Synergies (Run-Rate, Pre-Tax) | C20: =C11+C18 -> 130
B22: Synergy Phase-In Schedule
C23: Year 1 | D23: Year 2 | E23: Year 3 | F23: Run-Rate
B24: Realization % | C24: 0.35 | D24: 0.65 | E24: 0.9 | F24: 1
B25: Cost Synergies (€M) | C25: =C11*C24 -> 35 | D25: =C11*D24 -> 65 | E25: =C11*E24 -> 90 | F25: =C11*F24 -> 100
B26: Revenue Synergies (€M) | C26: =C18*C24 -> 10.5 | D26: =C18*D24 -> 19.5 | E26: =C18*E24 -> 27 | F26: =C18*F24 -> 30
B27: Total Pre-Tax Synergies (€M) | C27: =C25+C26 -> 45.5 | D27: =D25+D26 -> 84.5 | E27: =E25+E26 -> 117 | F27: =F25+F26 -> 130
B28: After-Tax Synergies (€M, 26% tax) | C28: =C27*(1-'DCF Valuation'!$C$10) -> 33.67 | D28: =D27*(1-'DCF Valuation'!$C$10) -> 62.53 | E28: =E27*(1-'DCF Valuation'!$C$10) -> 86.58 | F28: =F27*(1-'DCF Valuation'!$C$10) -> 96.2
B29: Integration Costs (one-time) | C29: 80 | D29: 40 | E29: 10 | F29: 0
B30: Net Synergy Benefit (€M) | C30: =C28-C29 -> -46.33 | D30: =D28-D29 -> 22.53 | E30: =E28-E29 -> 76.58 | F30: =F28-F29 -> 96.2
B32: Synergy NPV
B33: Discount Rate (WACC) | C33: ='DCF Valuation'!C14 -> 0.0854157
B34: PV of Synergy Cash Flows (phased Yr 1-3, then perpetuity from Yr 4) | C34: =C28/(1+C33)^1+D28/(1+C33)^2+E28/(1+C33)^3+F28/C33/(1+C33)^3 -> 1032.5452 | D34: Yr 1-3 discounted individually per phase-in schedule; Yr 4+ terminal perpetuity (run-rate after-tax syn / WACC) discounted to present at end of Yr 3
B35: Less: PV of Integration Costs | C35: =C29/(1+C33)+D29/(1+C33)^2+E29/(1+C33)^3 -> 115.47676
B36: Net Synergy Value (€M) | C36: =C34-C35 -> 917.06844
B37: Net Synergy Value per Cucinelli Share | C37: =C36/'Deal Overview'!$C$13 -> 13.486301
A40: Strictly Private & Confidential — For Discussion Purposes Only

Sheet Accretion - Dilution
B2: Accretion / Dilution Analysis (3-Year)
B4: Deal Financing Assumptions
B5: Total Equity Value (€M) | C5: ='Deal Overview'!C14 -> 8500
B6: Cash Consideration — 60% (€M) | C6: =C5*'Deal Overview'!$D$29 -> 5100
B7: Stock Consideration — 40% (€M) | C7: =C5*'Deal Overview'!$D$30 -> 3400
B8: Kering Share Price (€) | C8: 167.5
B9: New Kering Shares Issued (M) | C9: =C7/C8 -> 20.298507
B10: Existing Kering Shares (M) | C10: 122
B11: Pro Forma Share Count (M) | C11: =C10+C9 -> 142.29851
B13: Cash on Hand Used (€M) | C13: 1500
B14: New Debt Raised (€M) | C14: =C6-C13 -> 3600
B15: Blended Cost of New Debt (Pre-Tax) | C15: 0.048
B16: Tax Rate | C16: 0.26
B17: After-Tax Interest Expense (€M) | C17: =C14*C15*(1-C16) -> 127.872
B19: EPS Impact Analysis (3-Year)
C20: Standalone | D20: Year 1 PF | E20: Year 2 PF | F20: Year 3 PF
B21: Kering Net Income (€M) | C21: 2100 | D21: 2100 | E21: 2163 | F21: 2228
B22: Cucinelli Net Income (€M) | C22: — | D22: =Projections!C29 -> 218.32664 | E22: =Projections!D29 -> 245.11949 | F22: =Projections!E29 -> 272.36954
B23: After-Tax Synergies (€M) | C23: — | D23: ='Synergy Analysis'!C28 -> 33.67 | E23: ='Synergy Analysis'!D28 -> 62.53 | F23: ='Synergy Analysis'!E28 -> 86.58
B24: Less: After-Tax Interest (€M) | C24: — | D24: =-$C$17 -> -127.872 | E24: =-$C$17 -> -127.872 | F24: =-$C$17 -> -127.872
B25: Less: Integration Costs, After-Tax (€M) | C25: — | D25: =-'Synergy Analysis'!C29*(1-$C$16) -> -59.2 | E25: =-'Synergy Analysis'!D29*(1-$C$16) -> -29.6 | F25: =-'Synergy Analysis'!E29*(1-$C$16) -> -7.4
B26: Pro Forma Net Income (€M) | C26: =C21 -> 2100 | D26: =D21+D22+D23+D24+D25 -> 2164.9246 | E26: =E21+E22+E23+E24+E25 -> 2313.1775 | F26: =F21+F22+F23+F24+F25 -> 2451.6775
B27: Shares Outstanding (M) | C27: 122 | D27: =$C$11 -> 142.29851 | E27: =$C$11 -> 142.29851 | F27: =$C$11 -> 142.29851
B28: EPS (€) | C28: =C26/C27 -> 17.213115 | D28: =D26/D27 -> 15.213966 | E28: =E26/E27 -> 16.25581 | F28: =F26/F27 -> 17.229116
B29: Accretion / (Dilution) (€) | D29: =D28-$C$28 -> -1.9991489 | E29: =E28-$C$28 -> -0.9573048 | F29: =F28-$C$28 -> 0.016001608
B30: Accretion / (Dilution) % | D30: =D29/$C$28 -> -0.11614103 | E30: =E29/$C$28 -> -0.05561485 | F30: =F29/$C$28 -> 0.00092961725
B32: Breakeven Synergy Analysis
B33: Pre-Tax Synergies Required for Year 1 EPS Breakeven (€M) | C33: =($C$28*$C$11-$C$21-D22+$C$17+'Synergy Analysis'!C29*(1-$C$16))/(1-$C$16) -> 429.92689 | E33: vs. our estimate of €130M run-rate
B35: Note: Transaction is dilutive to Kering EPS in Year 1 (∼10%) but dilution narrows to ~3% by Year 3 as synergies ramp and Cucinelli earnings grow. Full accretion expected by Year 4–5 under base-case assumptions. Strategic rationale (Gucci diversification, quiet luxury positioning) must justify the near-term dilution.
A38: Strictly Private & Confidential — For Discussion Purposes Only

Sheet LBO Analysis
B2: Brunello Cucinelli S.p.A. — Leveraged Buyout Analysis
B3: Hypothetical PE Sponsor Acquisition — Floor Valuation Reference
B5: Transaction Assumptions | C5: Input | D5: Note
B6: Entry EV / LTM EBITDA (x) | C6: 18 | D6: Mid-market PE comp for luxury assets
B7: LTM EBITDA (€M) | C7: ='Cucinelli Financials'!H12 -> 346 | D7: FY2025 Actuals
B8: Entry Enterprise Value (€M) | C8: =C6*C7 -> 6228 | D8: EV = Entry Multiple x EBITDA
B9: Less: Net Debt (€M) | C9: ='Cucinelli Financials'!H42 -> 45 | D9: FY2025 Net Debt
B10: Equity Purchase Price (€M) | C10: =C8-C9 -> 6183 | D10: EV minus Net Debt
B12: Debt Financing (% of EV) | C12: 0.55 | D12: Conservative for luxury (typically 50-60%)
B13: Total Debt at Entry (€M) | C13: =C8*C12 -> 3425.4
B14: Sponsor Equity (€M) | C14: =C10-C13+C9 -> 2802.6 | D14: Equity Purchase Price minus Debt
B16: Senior Secured (% of total debt) | C16: 0.6
B17: Subordinated / Mezz (% of total debt) | C17: 0.4
B18: Senior Interest Rate | C18: 0.065 | D18: Spread ~275bps over 3.5% base
B19: Subordinated Interest Rate | C19: 0.095 | D19: Higher yield for mezz tranche
B20: Annual Amortisation (% of senior debt, p.a.) | C20: 0.05 | D20: 5% p.a. cash sweep
B22: Hold Period (years) | C22: 5 | D22: Standard 5-year hold
B23: Exit EV/EBITDA Multiple (x) | C23: 18 | D23: Same as entry (conservative base case)
B24: Tax Rate | C24: 0.26 | D24: Italian statutory
B25: Management Fee (% of EV, p.a.) | C25: 0.02 | D25: Typical 2% of entry EV p.a.
B27: Debt Schedule (EUR M)
C28: Entry | D28: Year 1 | E28: Year 2 | F28: Year 3 | G28: Year 4 | H28: Year 5
B29: Senior Secured Debt | C29: =C13*C16 -> 2055.24 | D29: =C29*(1-$C$20) -> 1952.478 | E29: =D29*(1-$C$20) -> 1854.8541 | F29: =E29*(1-$C$20) -> 1762.1114 | G29: =F29*(1-$C$20) -> 1674.0058 | H29: =G29*(1-$C$20) -> 1590.3055
B30: Subordinated / Mezz Debt (bullet) | C30: =C13*C17 -> 1370.16 | D30: =C30 -> 1370.16 | E30: =C30 -> 1370.16 | F30: =C30 -> 1370.16 | G30: =C30 -> 1370.16 | H30: =C30 -> 1370.16
B31: Total Debt | C31: =SUM(C29:C30) -> 3425.4 | D31: =SUM(D29:D30) -> 3322.638 | E31: =SUM(E29:E30) -> 3225.0141 | F31: =SUM(F29:F30) -> 3132.2714 | G31: =SUM(G29:G30) -> 3044.1658 | H31: =SUM(H29:H30) -> 2960.4655
B32: Interest Expense (EUR M) | D32: =C29*$C$18+C30*$C$19 -> 263.7558 | E32: =D29*$C$18+D30*$C$19 -> 257.07627 | F32: =E29*$C$18+E30*$C$19 -> 250.73072 | G32: =F29*$C$18+F30*$C$19 -> 244.70244 | H32: =G29*$C$18+G30*$C$19 -> 238.97558
B33: Debt / Entry EBITDA (x) | C33: =C31/C7 -> 9.9 | D33: =D31/C7 -> 9.603 | E33: =E31/C7 -> 9.32085 | F33: =F31/C7 -> 9.0528075 | G33: =G31/C7 -> 8.7981671 | H33: =H31/C7 -> 8.5562588
B35: Projected Cash Flow (EUR M)
D36: Year 1 | E36: Year 2 | F36: Year 3 | G36: Year 4 | H36: Year 5
B37: EBITDA | D37: =Projections!C21 -> 394.24 | E37: =Projections!D21 -> 437.3952 | F37: =Projections!E21 -> 480.6743 | G37: =Projections!F21 -> 523.18912 | H37: =Projections!G21 -> 563.98013
B38: Less: D&A | D38: =-Projections!C23 -> -88.704 | E38: =-Projections!D23 -> -95.15264 | F38: =-Projections!E23 -> -101.10735 | G38: =-Projections!F23 -> -106.41135 | H38: =-Projections!G23 -> -112.79603
B39: EBIT | D39: =D37+D38 -> 305.536 | E39: =E37+E38 -> 342.24256 | F39: =F37+F38 -> 379.56695 | G39: =G37+G38 -> 416.77777 | H39: =H37+H38 -> 451.18411
B40: Less: Interest Expense | D40: =-D32 -> -263.7558 | E40: =-E32 -> -257.07627 | F40: =-F32 -> -250.73072 | G40: =-G32 -> -244.70244 | H40: =-H32 -> -238.97558
B41: Less: Management Fee (2% of EV) | D41: =-$C$8*$C$25 -> -124.56 | E41: =-$C$8*$C$25 -> -124.56 | F41: =-$C$8*$C$25 -> -124.56 | G41: =-$C$8*$C$25 -> -124.56 | H41: =-$C$8*$C$25 -> -124.56
B42: EBT | D42: =SUM(D39:D41) -> -82.7798 | E42: =SUM(E39:E41) -> -39.39371 | F42: =SUM(F39:F41) -> 4.2762339 | G42: =SUM(G39:G41) -> 47.515331 | H42: =SUM(H39:H41) -> 87.648528
B43: Taxes (26%) | D43: =IF(D42>0,-D42*$C$24,0) -> 0 | E43: =IF(E42>0,-E42*$C$24,0) -> 0 | F43: =IF(F42>0,-F42*$C$24,0) -> -1.1118208 | G43: =IF(G42>0,-G42*$C$24,0) -> -12.353986 | H43: =IF(H42>0,-H42*$C$24,0) -> -22.788617
B44: Net Income | D44: =D42+D43 -> -82.7798 | E44: =E42+E43 -> -39.39371 | F44: =F42+F43 -> 3.1644131 | G44: =G42+G43 -> 35.161345 | H44: =H42+H43 -> 64.859911
B45: Plus: D&A | D45: =-D38 -> 88.704 | E45: =-E38 -> 95.15264 | F45: =-F38 -> 101.10735 | G45: =-G38 -> 106.41135 | H45: =-H38 -> 112.79603
B46: Less: CapEx | D46: =-Projections!C37 -> -98.56 | E46: =-Projections!D37 -> -107.4304 | F46: =-Projections!E37 -> -107.73734 | G46: =-Projections!F37 -> -115.27896 | H46: =-Projections!G37 -> -112.79603
B47: Less: Change in NWC | D47: =-Projections!C38 -> -6.4 | E47: =-Projections!D38 -> -6.336 | F47: =-Projections!E38 -> -6.13888 | G47: =-Projections!F38 -> -5.8012416 | H47: =-Projections!G38 -> -5.3205673
...

Sheet Valuation Summary
B2: Valuation Summary — Football Field (€ per Share)
B3: All values dynamically linked to model tabs
B5: Methodology | C5: Low | D5: Midpoint | E5: High
B6: 52-Week Trading Range | C6: 82 | D6: 98 | E6: 118 | G6: Bloomberg, Jun 2026
B7: DCF — Perpetuity Growth | C7: ='DCF Valuation'!C45*0.92 -> 63.994877 | D7: ='DCF Valuation'!C45 -> 69.559649 | E7: ='DCF Valuation'!C45*1.1 -> 76.515614 | G7: See DCF tab
B8: DCF — Exit Multiple | C8: ='DCF Valuation'!D45*0.87 -> 99.390261 | D8: ='DCF Valuation'!D45 -> 114.24168 | E8: ='DCF Valuation'!D45*1.17 -> 133.66276 | G8: See DCF tab
B9: Trading Comps (EV/EBITDA) | C9: ='Trading Comps'!D22*0.83 -> 65.306811 | D9: ='Trading Comps'!D22 -> 78.682904 | E9: ='Trading Comps'!D22*1.3 -> 102.28778 | G9: See Comps tab
B10: Precedent Transactions | C10: ='Precedent Transactions'!E18*0.58 -> 23.635 | D10: ='Precedent Transactions'!E18 -> 40.75 | E10: ='Precedent Transactions'!E19 -> 70.573529 | G10: See Precedents tab
B11: LBO Analysis (PE Floor) | C11: ='LBO Analysis'!C62*0.85 -> 77.2875 | D11: ='LBO Analysis'!C62 -> 90.926471 | E11: ='LBO Analysis'!C61 -> 91.588235 | G11: See LBO tab — PE buyer floor at 18x entry, 5yr hold
B13: Offer Price | D13: ='Deal Overview'!C10 -> 125 | G13: ='Deal Overview'!C12 -> 0.2755102
B15: Key Transaction Metrics
B16: Offer Price / Share | C16: ='Deal Overview'!C10 -> 125
B17: Premium to Unaffected | C17: ='Deal Overview'!C12 -> 0.2755102
B18: Implied EV/EBITDA | C18: ='Deal Overview'!C17 -> 24.696532
B19: Implied EV/Revenue | C19: ='Deal Overview'!C18 -> 6.6757812
B20: Year 1 EPS Accretion/(Dilution) | C20: ='Accretion - Dilution'!D30 -> -0.11614103
B21: Year 3 EPS Accretion/(Dilution) | C21: ='Accretion - Dilution'!F30 -> 0.00092961725
B22: Synergy NPV / Share | C22: ='Synergy Analysis'!C37 -> 13.486301
B23: Pro Forma Net Debt / EBITDA | C23: ='Sources & Uses'!C21 -> 2.6000825
B25: Recommendation
A31: Strictly Private & Confidential — For Discussion Purposes Only
B34: Chart Data (helper)
B35: Method | C35: Low | D35: Span
B36: 52-Week Range | C36: =C6 -> 82 | D36: =E6-C6 -> 36
B37: DCF Perpetuity | C37: =C7 -> 63.994877 | D37: =E7-C7 -> 12.520737
B38: DCF Exit Multiple | C38: =C8 -> 99.390261 | D38: =E8-C8 -> 34.272504
B39: Trading Comps | C39: =C9 -> 65.306811 | D39: =E9-C9 -> 36.980965
B40: Precedent Txns | C40: =C10 -> 23.635 | D40: =E10-C10 -> 46.938529
